Workbook
Name QA: BaseData!$A$2:$A$29

Sheet Instructions
B2: Prerequisite
B3: 1 | C3: You will need JIRA username and Token to use the tool. JIRA Username is your maxxton email address that you use for login to JIRA. Token needs to be created from https://support.atlassian.com/atlassian-account/docs/manage-api-tokens-for-your-atlassian-account/ Token creation is one time activity... Store your token as you can not retrieve it again from above link(only option will be to recreate it)
B4: 2 | C4: You will be asked to give permission from your Google Account when you run this tool for first time; and it's safe to do so ! ;)
B7: Schedule test case for execution
B8: 1 | C8: Go to worksheet of your module.
B9: 2 | C9: For the test case you want to schedule for execution, Update column H with value 'Y' indicating that you want to schedule it. You should set execution priority in column I and Execution By (assignee) in column J
B10: 3 | C10: From 'QA Project' menu, select 'Schedule Test Execution' option
B11: 4 | C11: You will be asked to provide JIRA username and Token.
B12: 5 | C12: You will also need to provide Release Information and Due Date for test result tickets.
B13: 6 | C13: Next give confirmation for scheduling selected test cases.
B14: 7 | C14: Column K and L should be populated with information about Test Result ticket and scheduling information.
B15: 8 | C15: You should also receive an email with details of newly created tickets.
B17: Creat new test case
B18: 1 | C18: Go to worksheet of your module.
B19: 2 | C19: Add value 'NEW' in column A of next empty row. Provide Summary, Priority, Component and Epic Link and Estimate(use JIRA format for estimate - eg 30m, 2h).
B20: 3 | C20: From 'QA Project' menu, select 'Create Test Case' option
B21: 4 | C21: You will be asked to provide JIRA username and Token.
B22: 5 | C22: Next give confirmation for uploading new test cases.
B23: 6 | C23: Column A should be populated with new test case key.
B24: 7 | C24: You should also receive an email with details of newly created tickets.

Sheet Summary
E1: Newyse | F1: CMS | G1: MXTS | H1: MCMS
F2: *v222* | G2: *2023_Week_27* | H2: *149*
C4: Team | D4: Total Test Cases | E4: Scheduled? | G4: Team | H4: Total Test Cases | I4: Scheduled?
C5: Newyse | D5: =Newyse!G2 -> 0 | E5: =countif(Newyse!L:L,$E$2) -> 0 | G5: Newyse | H5: =D5 -> 0 | I5: =E5 -> 0
C6: CMS | D6: =CMS!G2 -> 22 | E6: =countif(CMS!L:L,$F$2) -> 0 | G6: CMS | H6: =D6 -> 22 | I6: =E6 -> 0
C7: MCMS | D7: =MCMS!G2 -> 86 | E7: =countif(MCMS!L:L,$H$2) -> 0 | G7: MCMS | H7: =D7 -> 86 | I7: =E7 -> 0
C8: Rates | D8: =Rates!G2 -> 10 | E8: =countif(Rates!L:L,$G$2) -> 0 | G8: MXTS | H8: =sum(D8:D16) -> 199 | I8: =sum(E8:E16) -> 0
C9: Finance | D9: =Finance!G2 -> 11 | E9: =countif(Finance!L:L,$G$2) -> 0
C10: Operations | D10: =Operations!G2 -> 27 | E10: =countif(Operations!L:L,$G$2) -> 0
C11: Channel | D11: =Channel!G2 -> 17 | E11: =countif(Channel!L:L,$G$2) -> 0
C12: Revenue | D12: =Revenue!G2 -> 9 | E12: =countif(Revenue!L:L,$G$2) -> 0
C13: Reservations | D13: =Reservations!G2 -> 35 | E13: =countif(Reservations!L:L,$G$2) -> 0
C14: API | D14: =API!G2 -> 43 | E14: =countif(API!L:L,$G$2) -> 0
C15: CCM | D15: =CCM!G2 -> 22 | E15: =countif(CCM!L:L,$G$2) -> 0
C16: Content | D16: =Content!G2 -> 25 | E16: =countif(Content!L:L,$G$2) -> 0

Sheet Newyse
N1: Components | O1: Epic
F2: Total Test Cases | G2: =countifs(A:A,"<>NEW",A:A,"<>")-1 -> 0 | N2: CMS-Castle BM | O2: QA-1 | P2: Newyse Regression Test Cases
F3: Schedule? Y | G3: =countif(H:H,"=Y") -> 0 | N3: CMS-Castle MyEnv | O3: QA-24 | P3: CMS Regression Test Cases
F4: New Test Cases | G4: =COUNTIF(A:A,"=NEW") -> 0 | N4: CMS-Contempo BM | O4: QA-25 | P4: CMS Live Test Cases
N5: CMS-Contempo MyEnv | O5: QA-26 | P5: CMS Sanity Test Cases
A6: Key | B6: Summary | C6: Priority | D6: Component | E6: Epic Link | F6: Test Case Assignee | G6: Estimate | H6: Schedule ? | I6: Execution Priority | J6: Execution By | K6: Test Result Ticket | L6: Comments | N6: CMS-Deepcreek BM | O6: QA-54 | P6: Newyse Live Test Cases
N7: CMS-Deepcreek MyEnv | O7: QA-55 | P7: Newyse Sanity Test Cases
N8: CMS-Hogenboom BM | O8: QA-71 | P8: MXTS Sanity Test Cases
N9: CMS-Hogenboom MyEnv | O9: QA-72 | P9: MXTS Regression Test Cases
N10: CMS-Krim BM
N11: CMS-Krim MyEnv
N12: CMS-PerfectExp BM
N13: CMS-PerfectExp MyEnv
N14: CMS-Roompot BM
N15: CMS-Roompot MyEnv
N16: CMS-Siblu BM
N17: CMS-Siblu MyEnv
N18: MXTS-BackOffice Manager
N19: MXTS-Content Manager
N20: MXTS-Implementation Manager
N21: MXTS-Owner Manager
... N26: CMS-EuroparcsNL MyEnv

Sheet CMS
N1: Components | O1: Epic
F2: Total Test Cases | G2: =countifs(A:A,"<>NEW",A:A,"<>")-1 -> 22 | N2: CMS-Castle BM | O2: QA-1 | P2: Newyse Regression Test Cases
F3: Schedule? Y | G3: =countif(H:H,"=Y") -> 6 | N3: CMS-Castle MyEnv | O3: QA-24 | P3: CMS Regression Test Cases
F4: New Test Cases | G4: =COUNTIF(A:A,"=NEW") -> 0 | N4: CMS-Contempo BM | O4: QA-25 | P4: CMS Live Test Cases
N5: CMS-Contempo MyEnv | O5: QA-26 | P5: CMS Sanity Test Cases
A6: Key | B6: Summary | C6: Priority | D6: Component | E6: Epic Link | F6: Test Case Assignee | G6: Estimate | H6: Schedule ? | I6: Execution Priority | J6: Execution By | K6: Test Result Ticket | L6: Comments | N6: CMS-Deepcreek BM | O6: QA-54 | P6: Newyse Live Test Cases
A7: QA-73 | B7: RT_Castle Booking Module | C7: P3 | D7: CMS-Castle BM | E7: QA-24 | F7: Prajwal Atkare | G7: 180m | H7: N | I7: P3 | J7: Jyoti Koli | K7: =HYPERLINK("https://maxxton.atlassian.net/browse/QA-21812","QA-21812") -> QA-21812 | L7: Created on 2025-01-03 for release CMSv262 | N7: CMS-Deepcreek MyEnv | O7: QA-55 | P7: Newyse Sanity Test Cases
A8: QA-102 | B8: RT_Hogenboom Booking Module | C8: P3 | D8: CMS-Hogenboom BM | E8: QA-24 | F8: Jyoti Koli | G8: 180m | H8: N | I8: P3 | J8: Jyoti Koli | K8: =HYPERLINK("https://maxxton.atlassian.net/browse/QA-15771","QA-15771") -> QA-15771 | L8: Created on 2023-12-08 for release CMSv234 | N8: CMS-Hogenboom BM | O8: QA-71 | P8: MXTS Sanity Test Cases
A9: QA-103 | B9: RT_Roompot Booking Module | C9: P3 | D9: CMS-Roompot BM | E9: QA-24 | F9: Jyoti Koli | G9: 180m | H9: N | I9: P3 | J9: Jyoti Koli | K9: =HYPERLINK("https://maxxton.atlassian.net/browse/QA-22266","QA-22266") -> QA-22266 | L9: Created on 2025-01-31 for release CMSv64 | N9: CMS-Hogenboom MyEnv | O9: QA-72 | P9: MXTS Regression Test Cases
A10: QA-79 | B10: RT_Castle My Environment | C10: P3 | D10: CMS-Castle MyEnv | E10: QA-24 | F10: Sujata Pimpale | G10: 60m | H10: N | I10: P3 | J10: Jyoti Koli | K10: =HYPERLINK("https://maxxton.atlassian.net/browse/QA-22267","QA-22267") -> QA-22267 | L10: Created on 2025-01-31 for release CMSv64 | N10: CMS-Krim BM
A11: QA-82 | B11: RT_Hogenboom My Environment | C11: P3 | D11: CMS-Hogenboom MyEnv | E11: QA-24 | F11: Prajwal Atkare | G11: 60m | H11: N | I11: P3 | J11: Jyoti Koli | K11: =HYPERLINK("https://maxxton.atlassian.net/browse/QA-11981","QA-11981") -> QA-11981 | L11: Created on 2023-02-03 for release CMSv212 | N11: CMS-Krim MyEnv
A12: QA-83 | B12: RT_Krim My Environment | C12: P3 | D12: CMS-Krim MyEnv | E12: QA-24 | F12: Prajwal Atkare | G12: 60m | H12: N | I12: P3 | J12: Sujata Pimpale | K12: =HYPERLINK("https://maxxton.atlassian.net/browse/QA-22268","QA-22268") -> QA-22268 | L12: Created on 2025-01-31 for release CMSv64 | N12: CMS-PerfectExp BM
A13: QA-84 | B13: RT_Roompot My Environment | C13: P3 | D13: CMS-Roompot MyEnv | E13: QA-24 | F13: Jyoti Koli | G13: 60m | H13: N | I13: P3 | J13: Jyoti Koli | K13: =HYPERLINK("https://maxxton.atlassian.net/browse/QA-22269","QA-22269") -> QA-22269 | L13: Created on 2025-01-31 for release CMSv64 | N13: CMS-PerfectExp MyEnv
A14: QA-85 | B14: RT_Siblu My Environment | C14: P3 | D14: CMS-Siblu MyEnv | E14: QA-24 | F14: Prajwal Atkare | G14: 60m | H14: N | I14: P3 | J14: Sujata Pimpale | K14: =HYPERLINK("https://maxxton.atlassian.net/browse/QA-22270","QA-22270") -> QA-22270 | L14: Created on 2025-01-31 for release CMSv64 | N14: CMS-Roompot BM
A15: QA-3539 | B15: RT_CMS Webservices - TC1 | C15: P3 | D15: CMS-WebServices | E15: QA-24 | F15: Sujata Pimpale | H15: N | I15: P3 | J15: Jyoti Koli | K15: =HYPERLINK("https://maxxton.atlassian.net/browse/QA-22045","QA-22045") -> QA-22045 | L15: Created on 2025-01-17 for release CMSv263 | N15: CMS-Roompot MyEnv
A16: QA-1565 | B16: RT_Roompot Mobile Bookings Module | C16: P3 | D16: CMS-Roompot BM | E16: QA-24 | F16: Jyoti Koli | G16: 180m | H16: N | I16: P3 | J16: Jyoti Koli | K16: =HYPERLINK("https://maxxton.atlassian.net/browse/QA-22271","QA-22271") -> QA-22271 | L16: Created on 2025-01-31 for release CMSv64 | N16: CMS-Siblu BM
A17: QA-6801 | B17: RT_RCN My Environment | C17: P3 | D17: CMS-RCN MyEnv | E17: QA-24 | F17: Sujata Pimpale | G17: 90m | H17: N | I17: P3 | J17: Prajwal Atkare | K17: =HYPERLINK("https://maxxton.atlassian.net/browse/QA-21210","QA-21210") -> QA-21210 | L17: Created on 2024-11-25 for release CMSv259 | N17: CMS-Siblu MyEnv | Q17: =vlookup(J17,BaseData!A:B,2) -> 625a7ab04f1d57006a26d692
A18: QA-6802 | B18: RT_EuroparcsNL My Environment | C18: P3 | D18: CMS-EuroparcsNL MyEnv | E18: QA-24 | F18: Sujata Pimpale | G18: 90m | H18: N | I18: P3 | J18: Prajwal Atkare | K18: =HYPERLINK("https://maxxton.atlassian.net/browse/QA-21680","QA-21680") -> QA-21680 | L18: Created on 2024-12-20 for release CMSv261 | N18: MXTS-BackOffice Manager
A19: QA-86 | B19: LT_Castle Booking Module | C19: P2 | D19: CMS-Castle BM | E19: QA-25 | F19: Prajwal Atkare | G19: 20m | H19: N | I19: P2 | J19: Jyoti Koli | K19: =HYPERLINK("https://maxxton.atlassian.net/browse/QA-21841","QA-21841") -> QA-21841 | L19: Created on 2025-01-07 for release CMSv262 | N19: MXTS-Content Manager
A20: QA-89 | B20: LT_Hogenboom Booking Module | C20: P2 | D20: CMS-Hogenboom BM | E20: QA-25 | F20: Sujata Pimpale | G20: 20m | H20: N | I20: P2 | J20: Prajwal Atkare | K20: =HYPERLINK("https://maxxton.atlassian.net/browse/QA-19766","QA-19766") -> QA-19766 | L20: Created on 2024-09-03 for release CMSv253 | N20: MXTS-Implementation Manager
A21: QA-91 | B21: LT_Roompot Booking Module | C21: P2 | D21: CMS-Roompot BM | E21: QA-25 | F21: Jyoti Koli | G21: 20m | H21: Y | I21: P2 | J21: Jyoti Koli | K21: =HYPERLINK("https://maxxton.atlassian.net/browse/QA-22288","QA-22288") -> QA-22288 | L21: Created on 2025-02-04 for release CMSv264 | N21: MXTS-Owner Manager
A22: QA-93 | B22: LT_Castle My Environment | C22: P2 | D22: CMS-Castle MyEnv | E22: QA-25 | F22: Prajwal Atkare | G22: 20m | H22: Y | I22: P2 | J22: Jyoti Koli | K22: =HYPERLINK("https://maxxton.atlassian.net/browse/QA-22289","QA-22289") -> QA-22289 | L22: Created on 2025-02-04 for release CMSv264 | N22: MXTS-Rate Manager
A23: QA-96 | B23: LT_Hogenboom My Environment | C23: P2 | D23: CMS-Hogenboom MyEnv | E23: QA-25 | F23: Sujata Pimpale | G23: 20m | H23: N | I23: P2 | J23: Prajwal Atkare | K23: =HYPERLINK("https://maxxton.atlassian.net/browse/QA-19769","QA-19769") -> QA-19769 | L23: Created on 2024-09-03 for release CMSv253 | N23: MXTS-Reservation Manager
A24: QA-97 | B24: LT_Krim My Environment | C24: P2 | D24: CMS-Krim MyEnv | E24: QA-25 | F24: Prajwal Atkare | G24: 20m | H24: Y | I24: P2 | J24: Jyoti Koli | K24: =HYPERLINK("https://maxxton.atlassian.net/browse/QA-22290","QA-22290") -> QA-22290 | L24: Created on 2025-02-04 for release CMSv264 | N24: MXTS-PaymentService
A25: QA-98 | B25: LT_Roompot My Environment | C25: P2 | D25: CMS-Roompot MyEnv | E25: QA-25 | F25: Jyoti Koli | G25: 20m | H25: Y | I25: P2 | J25: Jyoti Koli | K25: =HYPERLINK("https://maxxton.atlassian.net/browse/QA-22291","QA-22291") -> QA-22291 | L25: Created on 2025-02-04 for release CMSv264 | N25: CMS-RCN MyEnv
A26: QA-99 | B26: LT_Siblu My Environment | C26: P2 | D26: CMS-Siblu MyEnv | E26: QA-25 | F26: Prajwal Atkare | G26: 20m | H26: Y | I26: P2 | J26: Jyoti Koli | K26: =HYPERLINK("https://maxxton.atlassian.net/browse/QA-22292","QA-22292") -> QA-22292 | L26: Created on 2025-02-04 for release CMSv264 | N26: CMS-EuroparcsNL MyEnv
A27: QA-1613 | B27: LT_Roompot Mobile Bookings module | C27: P2 | D27: CMS-Roompot BM | E27: QA-25 | F27: Jyoti Koli | G27: 20m | H27: Y | I27: P2 | J27: Jyoti Koli | K27: =HYPERLINK("https://maxxton.atlassian.net/browse/QA-22293","QA-22293") -> QA-22293 | L27: Created on 2025-02-04 for release CMSv264
A28: QA-6803 | B28: LT_EuroparcsNL My Environment | C28: P2 | D28: CMS-EuroparcsNL MyEnv | E28: QA-25 | F28: Sujata Pimpale | G28: 20m | H28: N | I28: P2 | J28: Prajwal Atkare | K28: =HYPERLINK("https://maxxton.atlassian.net/browse/QA-21689","QA-21689") -> QA-21689 | L28: Created on 2024-12-24 for release CMSv261

Sheet API
O1: Components | P1: Epic
F2: Total Test Cases | G2: =countifs(A:A,"<>NEW",A:A,"<>")-1 -> 43 | O2: API_Manager | P2: QA-1 | Q2: Newyse Regression Test Cases
F3: Schedule? Y | G3: =countif(H:H,"=Y") -> 17 | O3: API_PropertyDetails | P3: QA-24 | Q3: CMS Regression Test Cases
F4: New Test Cases | G4: =COUNTIF(A:A,"=NEW") -> 0 | O4: API_Customer Related | P4: QA-25 | Q4: CMS Live Test Cases
O5: API_BatchEventDelta | P5: QA-26 | Q5: CMS Sanity Test Cases
A6: Key | B6: Summary | C6: Priority | D6: Component | E6: Epic Link | F6: Test Case Assignee | G6: Estimate | H6: Schedule ? | I6: Execution Priority | J6: Execution By | K6: Test Result Ticket | L6: Comments | M6: Original Estimates | N6: Remaining Estimates | O6: API_Owner Related | P6: QA-54 | Q6: Newyse Live Test Cases
A7: QA-1429 | B7: RT_API_Property_Details_Resort_P1 | C7: P1 | D7: TPI_Resorts | E7: QA-1223 | G7: 30m | H7: Y | I7: P1 | J7: Anup Sinha | K7: =HYPERLINK("https://maxxton.atlassian.net/browse/QA-24859","QA-24859") -> QA-24859 | L7: Created on 2025-06-27 for release 2025_Week_27 | M7: 2 | O7: API_SearchAndBook | P7: QA-55 | Q7: Newyse Sanity Test Cases
A8: QA-1431 | B8: RT_API_Property_Details_Units_P1 | C8: P1 | D8: TPI_Units | E8: QA-1223 | G8: 2h | H8: Y | I8: P1 | J8: Dhiraj Bobade | K8: =HYPERLINK("https://maxxton.atlassian.net/browse/QA-24860","QA-24860") -> QA-24860 | L8: Created on 2025-06-27 for release 2025_Week_27 | M8: 2 | O8: API_Master Data | P8: QA-71 | Q8: MXTS Sanity Test Cases
A9: QA-1432 | B9: RT_API_Property_Details_Accommodationtypes_P1 | C9: P1 | D9: TPI_AccommodationTpes | E9: QA-1223 | G9: 2h | H9: Y | I9: P1 | J9: Dhiraj Bobade | K9: =HYPERLINK("https://maxxton.atlassian.net/browse/QA-24861","QA-24861") -> QA-24861 | L9: Created on 2025-06-27 for release 2025_Week_27 | M9: 2 | P9: QA-72 | Q9: MXTS Regression Test Cases
A10: QA-1433 | B10: RT_API_Property_Details_Accommodationtypes_P2 | C10: P2 | D10: TPI_AccommodationTpes | E10: QA-1223 | G10: 4h | H10: N | I10: P2 | J10: Anup Sinha | K10: =HYPERLINK("https://maxxton.atlassian.net/browse/QA-22977","QA-22977") -> QA-22977 | L10: Created on 2025-03-12 for release
A11: QA-1250 | B11: RT_API_Property_Details_Units_P2 | C11: P2 | D11: TPI_Units | E11: QA-1223 | G11: 4h | H11: N | I11: P2 | J11: Anup Sinha | K11: =HYPERLINK("https://maxxton.atlassian.net/browse/QA-22978","QA-22978") -> QA-22978 | L11: Created on 2025-03-12 for release
A12: QA-1430 | B12: RT_API_Property_Details_Resort_P2 | C12: P2 | D12: TPI_Resorts | E12: QA-1223 | G12: 4h | H12: N | I12: P2 | J12: Anup Sinha | K12: =HYPERLINK("https://maxxton.atlassian.net/browse/QA-22979","QA-22979") -> QA-22979 | L12: Created on 2025-03-12 for release
A13: QA-1473 | B13: RT_API_Property_Details_Offers_P1 | C13: P1 | D13: TPI_Offers | E13: QA-1223 | G13: 4h | H13: Y | I13: P1 | J13: Dhiraj Bobade | K13: =HYPERLINK("https://maxxton.atlassian.net/browse/QA-24862","QA-24862") -> QA-24862 | L13: Created on 2025-06-27 for release 2025_Week_27 | M13: 1
A14: QA-1475 | B14: RT_API_Property_Details_AddOn_P1 | C14: P1 | D14: TPI_AddOn | E14: QA-1223 | G14: 1h | H14: Y | I14: P1 | J14: Dhiraj Bobade | K14: =HYPERLINK("https://maxxton.atlassian.net/browse/QA-24863","QA-24863") -> QA-24863 | L14: Created on 2025-06-27 for release 2025_Week_27 | M14: 1
A15: QA-1501 | B15: RT_API_Property_Details_Amenity_P1 | C15: P1 | D15: TPI_Amenity | E15: QA-1223 | G15: 1h | H15: Y | I15: P1 | J15: Anup Sinha | K15: =HYPERLINK("https://maxxton.atlassian.net/browse/QA-24864","QA-24864") -> QA-24864 | L15: Created on 2025-06-27 for release 2025_Week_27 | M15: 30m
A16: QA-1534 | B16: API_Customer_P1 | C16: P1 | D16: TPI_Customer | E16: QA-1223 | G16: 4h | H16: Y | I16: P1 | J16: Aparna Shinde | K16: =HYPERLINK("https://maxxton.atlassian.net/browse/QA-24865","QA-24865") -> QA-24865 | L16: Created on 2025-06-27 for release 2025_Week_27 | M16: 1
A17: QA-1512 | B17: API_Batches/Delta/Events _Event_P1 | C17: P1 | D17: TPI_Events | E17: QA-1223 | G17: 2h | H17: N | I17: P1 | J17: Aparna Shinde | K17: =HYPERLINK("https://maxxton.atlassian.net/browse/QA-22740","QA-22740") -> QA-22740 | L17: Created on 2025-03-07 for release 2025_Week_11 | M17: 30m
A18: QA-1513 | B18: API_Owner_P1 | C18: P1 | D18: TPI_owners | E18: QA-1223 | G18: 4h | H18: Y | I18: P1 | J18: Anup Sinha | K18: =HYPERLINK("https://maxxton.atlassian.net/browse/QA-24866","QA-24866") -> QA-24866 | L18: Created on 2025-06-27 for release 2025_Week_27 | M18: 2
A19: QA-1514 | B19: API_Owner_P2 | C19: P2 | D19: TPI_owners | E19: QA-1223 | G19: 5h | H19: N | I19: P2 | J19: Aparna Shinde | K19: =HYPERLINK("https://maxxton.atlassian.net/browse/QA-22980","QA-22980") -> QA-22980 | L19: Created on 2025-03-12 for release
A20: QA-2737 | B20: API_Accommodation_Search | C20: P1 | D20: TPI_SearchAndBook | E20: QA-1223 | G20: 1h | H20: Y | I20: P1 | J20: Aparna Shinde | K20: =HYPERLINK("https://maxxton.atlassian.net/browse/QA-24867","QA-24867") -> QA-24867 | L20: Created on 2025-06-27 for release 2025_Week_27 | M20: 30m
A21: QA-2738 | B21: API_Accommodation_Range_Search | C21: P1 | D21: TPI_SearchAndBook | E21: QA-1223 | G21: 1h | H21: Y | I21: P1 | J21: Anup Sinha | K21: =HYPERLINK("https://maxxton.atlassian.net/browse/QA-24868","QA-24868") -> QA-24868 | L21: Created on 2025-06-27 for release 2025_Week_27 | M21: 30m
A22: QA-1508 | B22: API_Reservations_P1_Reservation_proposal | C22: P1 | D22: TPI_Reservations/TPI_ReservationProposal | E22: QA-1223 | G22: 2h | H22: Y | I22: P1 | J22: Aparna Shinde | K22: =HYPERLINK("https://maxxton.atlassian.net/browse/QA-24869","QA-24869") -> QA-24869 | L22: Created on 2025-06-27 for release 2025_Week_27 | M22: 1h 30m
A23: QA-1531 | B23: API_Reservations_P1_Reservations | C23: P1 | D23: TPI_Reservations | E23: QA-1223 | G23: 2h | H23: Y | I23: P1 | J23: Aparna Shinde | K23: =HYPERLINK("https://maxxton.atlassian.net/browse/QA-24870","QA-24870") -> QA-24870 | L23: Created on 2025-06-27 for release 2025_Week_27 | M23: 1h 30m
A24: QA-1532 | B24: API_Reservations_P1_Others | C24: P1 | D24: TPI_Reservations | E24: QA-1223 | G24: 4h | H24: Y | I24: P1 | J24: Anup Sinha | K24: =HYPERLINK("https://maxxton.atlassian.net/browse/QA-24871","QA-24871") -> QA-24871 | L24: Created on 2025-06-27 for release 2025_Week_27 | M24: 3h
A25: QA-1506 | B25: API_Master Data_P1 | C25: P1 | D25: TPI_MasterData | E25: QA-1223 | G25: 2h | H25: Y | I25: P1 | J25: Aparna Shinde | K25: =HYPERLINK("https://maxxton.atlassian.net/browse/QA-24872","QA-24872") -> QA-24872 | L25: Created on 2025-06-27 for release 2025_Week_27 | M25: 45m
A26: QA-9613 | B26: To view recent requests of an API user | C26: P3 | D26: TPI_IntegrationManager | E26: QA-9605 | G26: 2h | H26: N | I26: P3 | J26: Aparna Shinde | K26: =HYPERLINK("https://maxxton.atlassian.net/browse/QA-17792","QA-17792") -> QA-17792 | L26: Created on 2024-05-02 for release 2024_Week_19 | M26: 15m
A27: QA-9606 | B27: API user Creation | C27: P3 | D27: TPI_IntegrationManager | E27: QA-9605 | G27: 30m | H27: N | I27: P3 | J27: Aparna Shinde | K27: =HYPERLINK("https://maxxton.atlassian.net/browse/QA-17793","QA-17793") -> QA-17793 | L27: Created on 2024-05-02 for release 2024_Week_19 | M27: 1h
A28: QA-9607 | B28: To view and add new credentials for an API user | C28: P3 | D28: TPI_IntegrationManager | E28: QA-9605 | G28: 30m | H28: N | I28: P3 | J28: Aparna Shinde | K28: =HYPERLINK("https://maxxton.atlassian.net/browse/QA-17794","QA-17794") -> QA-17794 | L28: Created on 2024-05-02 for release 2024_Week_19 | M28: 30m
A29: QA-9608 | B29: To view and update Linked Locations for an API user | C29: P3 | D29: TPI_IntegrationManager | E29: QA-9605 | G29: 30m | H29: N | I29: P3 | J29: Aparna Shinde | K29: =HYPERLINK("https://maxxton.atlassian.net/browse/QA-17795","QA-17795") -> QA-17795 | L29: Created on 2024-05-02 for release 2024_Week_19 | M29: 30m
A30: QA-9609 | B30: Updating Permissions for an API user | C30: P3 | D30: TPI_IntegrationManager | E30: QA-9605 | G30: 30m | H30: N | I30: P3 | J30: Aparna Shinde | K30: =HYPERLINK("https://maxxton.atlassian.net/browse/QA-17796","QA-17796") -> QA-17796 | L30: Created on 2024-05-02 for release 2024_Week_19 | M30: 30m
A31: QA-9610 | B31: Calculating API usage costs | C31: P3 | D31: TPI_IntegrationManager | E31: QA-9605 | G31: 30m | H31: N | I31: P3 | J31: Aparna Shinde | K31: =HYPERLINK("https://maxxton.atlassian.net/browse/QA-17797","QA-17797") -> QA-17797 | L31: Created on 2024-05-02 for release 2024_Week_19 | M31: 20m
A32: QA-9611 | B32: To view and add new admin organizations for an API user | C32: P3 | D32: TPI_IntegrationManager | E32: QA-9605 | G32: 30m | H32: N | I32: P3 | J32: Aparna Shinde | K32: =HYPERLINK("https://maxxton.atlassian.net/browse/QA-17798","QA-17798") -> QA-17798 | L32: Created on 2024-05-02 for release 2024_Week_19 | M32: 30m
A33: QA-9612 | B33: Searching an API user and viewing API documentation | C33: P3 | D33: TPI_IntegrationManager | E33: QA-9605 | G33: 30m | H33: N | I33: P3 | J33: Aparna Shinde | K33: =HYPERLINK("https://maxxton.atlassian.net/browse/QA-17799","QA-17799") -> QA-17799 | L33: Created on 2024-05-02 for release 2024_Week_19 | M33: 15m | O33: Anup Sinha | P33: =COUNTIF(J7:J41, "*Anup Sinha*") -> 13
A34: QA-1505 | B34: API_Representations_P1 | C34: P1 | D34: TPI_Representations | E34: QA-1223 | G34: 2h | H34: N | I34: P1 | J34: Anup Sinha | K34: =HYPERLINK("https://maxxton.atlassian.net/browse/QA-22981","QA-22981") -> QA-22981 | L34: Created on 2025-03-12 for release | O34: Rohan Bhegade | P34: =COUNTIF(J7:J41, "*Rohan Bhegade*") -> 0
A35: QA-1503 | B35: API_UnitReservability/Reservability_P1 | C35: P1 | D35: TPI_Reservability | E35: QA-1223 | G35: 2h | H35: N | I35: P1 | J35: Anup Sinha | K35: =HYPERLINK("https://maxxton.atlassian.net/browse/QA-22982","QA-22982") -> QA-22982 | L35: Created on 2025-03-12 for release | O35: Aparna Shinde | P35: =COUNTIF(J1:J41, "Aparna Shinde") -> 16
A36: =HYPERLINK("https://maxxton.atlassian.net/browse/QA-10650","QA-10650") -> QA-10650 | B36: API_Housekeepings | C36: P1 | D36: TPI_Housekeeping | E36: QA-1223 | G36: 30m | H36: Y | I36: P1 | J36: Anup Sinha | K36: =HYPERLINK("https://maxxton.atlassian.net/browse/QA-24873","QA-24873") -> QA-24873 | L36: Created on 2025-06-27 for release 2025_Week_27 | M36: 1
A37: =HYPERLINK("https://maxxton.atlassian.net/browse/QA-11287","QA-11287") -> QA-11287 | B37: API_Infotexts_P1 | C37: P1 | D37: TPI_Infotexts | E37: QA-1223 | G37: 1h | H37: Y | I37: P1 | J37: Dhiraj Bobade | K37: =HYPERLINK("https://maxxton.atlassian.net/browse/QA-24874","QA-24874") -> QA-24874 | L37: Created on 2025-06-27 for release 2025_Week_27 | M37: 1
A38: =HYPERLINK("https://maxxton.atlassian.net/browse/QA-14981","QA-14981") -> QA-14981 | B38: API_Employee_P1 | C38: P1 | D38: TPI_Employee | E38: QA-1223 | G38: 60m | H38: N | I38: P1 | J38: Aparna Shinde | K38: =HYPERLINK("https://maxxton.atlassian.net/browse/QA-22985","QA-22985") -> QA-22985 | L38: Created on 2025-03-12 for release | M38: 1
A39: =HYPERLINK("https://maxxton.atlassian.net/browse/QA-15098","QA-15098") -> QA-15098 | B39: API_Operations_P1 | C39: P1 | D39: TPI_Operations | E39: QA-1223 | G39: 1h | H39: Y | I39: P1 | J39: Dhiraj Bobade | K39: =HYPERLINK("https://maxxton.atlassian.net/browse/QA-24875","QA-24875") -> QA-24875 | L39: Created on 2025-06-27 for release 2025_Week_27 | M39: 1
A40: QA-15099 | B40: API_Packages_P2 | C40: P3 | D40: TPI_Packages | E40: QA-1223 | G40: 30m | H40: N | I40: P3 | J40: Anup Sinha | K40: =HYPERLINK("https://maxxton.atlassian.net/browse/QA-22987","QA-22987") -> QA-22987 | L40: Created on 2025-03-12 for release | M40: 1
...

Sheet Revenue
O1: Components | P1: Epic
F2: Total Test Cases | G2: =countifs(A:A,"<>NEW",A:A,"<>")-1 -> 9 | O2: RevM_Autopilot | P2: QA-9421 | Q2: Revenue Manager Regression Test Cases
F3: Schedule? Y | G3: =countif(H:H,"=Y") -> 5 | O3: RevM_Budgets
F4: New Test Cases | G4: =COUNTIF(A:A,"=NEW") -> 0 | O4: RevM_Trends_page
F5: ciTSS7f3VPYW8Af3i2ZO923A | O5: RevM_Notification
A6: Key | B6: Summary | C6: Priority | D6: Component | E6: Epic Link | F6: Test Case Assignee | G6: Estimate | H6: Schedule ? | I6: Execution Priority | J6: Execution By | K6: Test Result Ticket | L6: Comments | M6: Original Estimates | N6: Remaining Estimates | O6: RevM_Monitors
A7: QA-9457 | B7: RT_Autopilot | C7: P3 | D7: RevM_Autopilot | E7: QA-9421 | F7: Mahesh Pawar | G7: 2h | H7: N | I7: P3 | J7: Mahesh Pawar | K7: =HYPERLINK("https://maxxton.atlassian.net/browse/QA-27256","QA-27256") -> QA-27256 | L7: Created on 2025-11-28 for release 2025_Week_49 | M7: 2h | N7: 30m | O7: RevM_Insight
A8: QA-9458 | B8: RT_Budget | C8: P3 | D8: RevM_Budgets | E8: QA-9421 | F8: Mahesh Pawar | G8: 90m | H8: N | I8: P3 | J8: Mahesh Pawar | K8: =HYPERLINK("https://maxxton.atlassian.net/browse/QA-27257","QA-27257") -> QA-27257 | L8: Created on 2025-11-28 for release 2025_Week_49 | M8: 1h 30m | N8: 30m | O8: RevM_Collection
A9: QA-9459 | B9: RT_Collection | C9: P3 | D9: RevM_Collection | E9: QA-9421 | F9: Mahesh Pawar | G9: 3h | H9: Y | I9: P3 | J9: Mahesh Pawar | K9: =HYPERLINK("https://maxxton.atlassian.net/browse/QA-28695","QA-28695") -> QA-28695 | L9: Created on 2026-03-06 for release 2026_Week_11 | M9: 3h | N9: 20m | O9: RevM_Dashboard
A10: QA-9460 | B10: RT_Yearly_insights | C10: P3 | D10: RevM_Yearly_insights | E10: QA-9421 | F10: Mahesh Pawar | G10: 1h 30m | H10: Y | I10: P3 | J10: Mahesh Pawar | K10: =HYPERLINK("https://maxxton.atlassian.net/browse/QA-28696","QA-28696") -> QA-28696 | L10: Created on 2026-03-06 for release 2026_Week_11 | M10: 1h 30m | N10: 30m | O10: RevM_Optimized_Rates
A11: =HYPERLINK("https://maxxton.atlassian.net/browse/QA-9463","QA-9463") -> QA-9463 | B11: RT_Insights | C11: P3 | D11: RevM_Insight | E11: QA-9421 | F11: Mahesh Pawar | G11: 210m | H11: Y | I11: P3 | J11: Mahesh Pawar | K11: =HYPERLINK("https://maxxton.atlassian.net/browse/QA-28697","QA-28697") -> QA-28697 | L11: Created on 2026-03-06 for release 2026_Week_11 | M11: 3h 30m | N11: 1h 30m
A12: =HYPERLINK("https://maxxton.atlassian.net/browse/QA-9465","QA-9465") -> QA-9465 | B12: RT_Notifications | C12: P3 | D12: RevM_Notification | E12: QA-9421 | F12: Narendra Deshmane | G12: 3h | H12: N | I12: P3 | J12: Narendra Deshmane | K12: =HYPERLINK("https://maxxton.atlassian.net/browse/QA-27261","QA-27261") -> QA-27261 | L12: Created on 2025-11-28 for release 2025_Week_49 | M12: 3h | N12: 1h 20m
A13: =HYPERLINK("https://maxxton.atlassian.net/browse/QA-9466","QA-9466") -> QA-9466 | B13: RT_Trends_page | C13: P3 | D13: RevM_Trends_page | E13: QA-9421 | F13: Narendra Deshmane | G13: 90m | H13: N | I13: P3 | J13: Narendra Deshmane | K13: =HYPERLINK("https://maxxton.atlassian.net/browse/QA-27262","QA-27262") -> QA-27262 | L13: Created on 2025-11-28 for release 2025_Week_49 | M13: 1h 30m | N13: 45m
A14: =HYPERLINK("https://maxxton.atlassian.net/browse/QA-9864","QA-9864") -> QA-9864 | B14: RT_Rate_updates | C14: P3 | D14: RevM_Optimized_Rates | E14: QA-9421 | F14: Narendra Deshmane | G14: 3h | H14: Y | I14: P3 | J14: Narendra Deshmane | K14: =HYPERLINK("https://maxxton.atlassian.net/browse/QA-28698","QA-28698") -> QA-28698 | L14: Created on 2026-03-06 for release 2026_Week_11 | M14: 3h | N14: 45m
A15: =HYPERLINK("https://maxxton.atlassian.net/browse/QA-15665","QA-15665") -> QA-15665 | B15: RT_Rate_Generator | C15: P3 | D15: RevM_Rate_Generator | E15: QA-9421 | F15: Narendra Deshmane | G15: 3h | H15: Y | I15: P3 | J15: Narendra Deshmane | K15: =HYPERLINK("https://maxxton.atlassian.net/browse/QA-28699","QA-28699") -> QA-28699 | L15: Created on 2026-03-06 for release 2026_Week_11 | M15: 3h | N15: 1h 15m
L16: Total hrs | M16: 22h | N16: 7h 41m

Sheet MCMS
F2: Total Test Cases | G2: =countifs(A:A,"<>NEW",A:A,"<>")-1 -> 86
F3: Schedule? Y | G3: =countif(H:H,"=Y") -> 27
F4: New Test Cases | G4: =COUNTIF(A:A,"=NEW") -> 0
A6: Key | B6: Summary | C6: Priority | D6: Component | E6: Epic Link | F6: Test Case Assignee | G6: Estimate | H6: Schedule ? | I6: Execution Priority | J6: Execution By
A7: QA-6877 | B7: LT_MCMS FMC BM | C7: P2 | D7: MCMS_Booking Module | E7: QA-2184 | G7: 1h 30m | H7: Y | I7: P2 | J7: Chandra Mohanty | K7: =HYPERLINK("https://maxxton.atlassian.net/browse/QA-29033","QA-29033") -> QA-29033 | L7: Created on 2026-04-01 for release Sprint_221
A8: QA-6879 | B8: LT_MCMS KRM BM | C8: P2 | D8: MCMS_Booking Module | E8: QA-2184 | G8: 1h 30m | H8: Y | I8: P2 | J8: Chandra Mohanty | K8: =HYPERLINK("https://maxxton.atlassian.net/browse/QA-29034","QA-29034") -> QA-29034 | L8: Created on 2026-04-01 for release Sprint_221
A9: QA-6880 | B9: LT_MCMS WEE BM | C9: P2 | D9: MCMS_Booking Module | E9: QA-2184 | G9: 1h 30m | H9: Y | I9: P2 | J9: Sujata Pimpale | K9: =HYPERLINK("https://maxxton.atlassian.net/browse/QA-29035","QA-29035") -> QA-29035 | L9: Created on 2026-04-01 for release Sprint_221
A10: QA-6881 | B10: LT_MCMS CSH BM | C10: P2 | D10: MCMS_Booking Module | E10: QA-2184 | G10: 1h 30m | H10: Y | I10: P2 | J10: Amruta Jadhav | K10: =HYPERLINK("https://maxxton.atlassian.net/browse/QA-29036","QA-29036") -> QA-29036 | L10: Created on 2026-04-01 for release Sprint_221
A11: QA-6882 | B11: LT_MCMS SA BM | C11: P2 | D11: MCMS_Booking Module | E11: QA-2184 | G11: 1h 30m | H11: Y | I11: P2 | J11: Amruta Jadhav | K11: =HYPERLINK("https://maxxton.atlassian.net/browse/QA-29037","QA-29037") -> QA-29037 | L11: Created on 2026-04-01 for release Sprint_221
A12: QA-6883 | B12: LT_MCMS ONS BM | C12: P2 | D12: MCMS_Booking Module | E12: QA-2184 | G12: 1h 30m | H12: Y | I12: P2 | J12: Amruta Jadhav | K12: =HYPERLINK("https://maxxton.atlassian.net/browse/QA-29038","QA-29038") -> QA-29038 | L12: Created on 2026-04-01 for release Sprint_221
A13: QA-8382 | B13: LT_MCMS LSH BM | C13: P2 | D13: MCMS_Booking Module | E13: QA-2184 | G13: 1h 30m | H13: Y | I13: P2 | J13: Sujata Pimpale | K13: =HYPERLINK("https://maxxton.atlassian.net/browse/QA-29039","QA-29039") -> QA-29039 | L13: Created on 2026-04-01 for release Sprint_221
A14: =HYPERLINK("https://maxxton.atlassian.net/browse/QA-17365","QA-17365") -> QA-17365 | B14: LT_MCMS COF BM | C14: P2 | D14: MCMS_Booking Module | E14: QA-2184 | F14: Sujata Pimpale | G14: 1h 30m | H14: Y | I14: P2 | J14: Amruta Jadhav | K14: =HYPERLINK("https://maxxton.atlassian.net/browse/QA-29040","QA-29040") -> QA-29040 | L14: Created on 2026-04-01 for release Sprint_221
A15: QA-6886 | B15: LT_MCMS NRT BM | C15: P2 | D15: MCMS_Booking Module | E15: QA-2184 | G15: 1h 30m | H15: Y | I15: P2 | J15: Amruta Jadhav | K15: =HYPERLINK("https://maxxton.atlassian.net/browse/QA-29041","QA-29041") -> QA-29041 | L15: Created on 2026-04-01 for release Sprint_221
A16: =HYPERLINK("https://maxxton.atlassian.net/browse/QA-22306","QA-22306") -> QA-22306 | B16: LT_MCMS SAN BM | C16: P3 | D16: MCMS_Booking Module | E16: QA-2184 | F16: Sujata Pimpale | G16: 1h 30m | H16: Y | I16: P3 | J16: Amruta Jadhav | K16: =HYPERLINK("https://maxxton.atlassian.net/browse/QA-29042","QA-29042") -> QA-29042 | L16: Created on 2026-04-01 for release Sprint_221
A17: QA-6878 | B17: LT_MCMS RVP QURIOS BM | C17: P3 | D17: MCMS_Booking Module | E17: QA-2184 | G17: 60m | H17: N | I17: P3
A18: QA-6884 | B18: LT_MCMS VDT BM | C18: P3 | D18: MCMS_Booking Module | E18: QA-2184 | G18: 1h 30m | H18: N | I18: P3 | J18: Chandra Mohanty | K18: =HYPERLINK("https://maxxton.atlassian.net/browse/QA-27854","QA-27854") -> QA-27854
A19: QA-6885 | B19: LT_MCMS ALP BM | C19: P3 | D19: MCMS_Booking Module | E19: QA-2184 | G19: 1h 30m | H19: N | I19: P3 | J19: Chandra Mohanty | K19: =HYPERLINK("https://maxxton.atlassian.net/browse/QA-27855","QA-27855") -> QA-27855
A20: QA-6983 | B20: RT_WM_Categories | C20: P3 | D20: MCMS_WM_Categories | E20: QA-2184 | G20: 60m | H20: N | I20: P3 | J20: Amruta Jadhav | K20: =HYPERLINK("https://maxxton.atlassian.net/browse/QA-26108","QA-26108") -> QA-26108
A21: QA-6984 | B21: RT_WM_CRP | C21: P3 | D21: MCMS_WM_CustomResultPanels | E21: QA-2184 | G21: 60m | H21: N | I21: P3 | J21: Chandra Mohanty | K21: =HYPERLINK("https://maxxton.atlassian.net/browse/QA-26109","QA-26109") -> QA-26109
A22: QA-6985 | B22: RT_WM_Datalayers | C22: P3 | D22: MCMS_WM_Datalayers | E22: QA-2184 | G22: 60m | H22: N | I22: P3 | J22: Amruta Jadhav
A23: QA-6986 | B23: RT_WM_Dynamic Sitemaps | C23: P3 | D23: MCMS_WM_DynamicSitemaps | E23: QA-2184 | G23: 60m | H23: N | I23: P3 | J23: Amruta Jadhav
A24: QA-6987 | B24: RT_WM_Flows | C24: P3 | D24: MCMS_WM_Flows | E24: QA-2184 | G24: 60m | H24: N | I24: P3 | J24: Amruta Jadhav
A25: QA-6988 | B25: RT_WM_Forms | C25: P3 | D25: MCMS_WM_Forms | E25: QA-2184 | G25: 60m | H25: N | I25: P3 | J25: Amruta Jadhav | K25: =HYPERLINK("https://maxxton.atlassian.net/browse/QA-28277","QA-28277") -> QA-28277
A26: QA-6989 | B26: RT_WM_Free Search | C26: P3 | D26: MCMS_WM_FreeSearch | E26: QA-2184 | G26: 60m | H26: N | I26: P3 | J26: Amruta Jadhav
A27: QA-6990 | B27: RT_WM_Locale | C27: P3 | D27: MCMS_WM_Languages | E27: QA-2184 | G27: 60m | H27: N | I27: P3 | J27: Amruta Jadhav | K27: =HYPERLINK("https://maxxton.atlassian.net/browse/QA-26110","QA-26110") -> QA-26110
A28: QA-6991 | B28: RT_WM_Translations | C28: P3 | D28: MCMS_WM_Languages | E28: QA-2184 | G28: 60m | H28: N | I28: P3 | J28: Amruta Jadhav
A29: QA-6992 | B29: RT_WM_Menus | C29: P3 | D29: MCMS_WM_Menus | E29: QA-2184 | G29: 60m | H29: N | I29: P3 | J29: Amruta Jadhav | K29: =HYPERLINK("https://maxxton.atlassian.net/browse/QA-27582","QA-27582") -> QA-27582
A30: QA-6993 | B30: RT_WM_CMS Settings | C30: P3 | D30: MCMS_WM_OverallSettings | E30: QA-2184 | G30: 60m | H30: N | I30: P3 | J30: Amruta Jadhav | K30: =HYPERLINK("https://maxxton.atlassian.net/browse/QA-25388","QA-25388") -> QA-25388
A31: QA-6994 | B31: RT_WM_Pages | C31: P3 | D31: MCMS_WM_Pages | E31: QA-2184 | G31: 60m | H31: N | I31: P3 | J31: Amruta Jadhav | K31: =HYPERLINK("https://maxxton.atlassian.net/browse/QA-28278","QA-28278") -> QA-28278
A32: QA-6995 | B32: RT_WM_Posts | C32: P3 | D32: MCMS_WM_Posts | E32: QA-2184 | G32: 60m | H32: N | I32: P3 | J32: Amruta Jadhav | K32: =HYPERLINK("https://maxxton.atlassian.net/browse/QA-28279","QA-28279") -> QA-28279
A33: QA-6996 | B33: RT_WM_Sites | C33: P3 | D33: MCMS_WM_Sites | E33: QA-2184 | G33: 60m | H33: N | I33: P3 | J33: Amruta Jadhav | K33: =HYPERLINK("https://maxxton.atlassian.net/browse/QA-27585","QA-27585") -> QA-27585
A34: QA-6997 | B34: RT_WM_Templates | C34: P3 | D34: MCMS_WM_Templates | E34: QA-2184 | G34: 60m | H34: N | I34: P3 | J34: Amruta Jadhav | K34: =HYPERLINK("https://maxxton.atlassian.net/browse/QA-28280","QA-28280") -> QA-28280
A35: QA-6998 | B35: RT_WM_Web Contents | C35: P3 | D35: MCMS_WM_WebContents | E35: QA-2184 | G35: 60m | H35: N | I35: P3 | J35: Amruta Jadhav | K35: =HYPERLINK("https://maxxton.atlassian.net/browse/QA-28281","QA-28281") -> QA-28281
A36: QA-6999 | B36: RT_WM_Price Widget | C36: P3 | D36: MCMS_WM_Widgets | E36: QA-2184 | G36: 60m | H36: N | I36: P3 | J36: Amruta Jadhav | K36: =HYPERLINK("https://maxxton.atlassian.net/browse/QA-26114","QA-26114") -> QA-26114
A37: QA-7000 | B37: RT_WM_Containers Widget | C37: P3 | D37: MCMS_WM_Widgets | E37: QA-2184 | G37: 60m | H37: N | I37: P3 | J37: Amruta Jadhav | K37: =HYPERLINK("https://maxxton.atlassian.net/browse/QA-26115","QA-26115") -> QA-26115
A38: QA-7001 | B38: RT_WM_Button Widget | C38: P3 | D38: MCMS_WM_Widgets | E38: QA-2184 | G38: 60m | H38: N | I38: P3 | J38: Amruta Jadhav | K38: =HYPERLINK("https://maxxton.atlassian.net/browse/QA-27588","QA-27588") -> QA-27588
A39: QA-7002 | B39: RT_WM_Map Widget | C39: P3 | D39: MCMS_WM_Widgets | E39: QA-2184 | G39: 60m | H39: N | I39: P3 | J39: Amruta Jadhav | K39: =HYPERLINK("https://maxxton.atlassian.net/browse/QA-28282","QA-28282") -> QA-28282
A40: QA-7003 | B40: RT_WM_Gallery Widget | C40: P3 | D40: MCMS_WM_Widgets | E40: QA-2184 | G40: 60m | H40: N | I40: P3 | J40: Amruta Jadhav | K40: =HYPERLINK("https://maxxton.atlassian.net/browse/QA-28283","QA-28283") -> QA-28283
A41: QA-7004 | B41: RT_WM_Dynamic Container Widget | C41: P3 | D41: MCMS_WM_Widgets | E41: QA-2184 | G41: 60m | H41: N | I41: P3 | J41: Amruta Jadhav | K41: =HYPERLINK("https://maxxton.atlassian.net/browse/QA-26116","QA-26116") -> QA-26116
A42: QA-7005 | B42: RT_WM_Search Widget | C42: P3 | D42: MCMS_WM_Widgets | E42: QA-2184 | G42: 60m | H42: N | I42: P3 | J42: Amruta Jadhav
...

Sheet Finance
O1: Components | P1: Epic
F2: Total Test Cases | G2: =countifs(A:A,"<>NEW",A:A,"<>")-1 -> 11 | O2: CMS-Castle BM | P2: QA-1 | Q2: Newyse Regression Test Cases
F3: Schedule? Y | G3: =countif(H:H,"=Y") -> 11 | O3: CMS-Castle MyEnv | P3: QA-24 | Q3: CMS Regression Test Cases
F4: New Test Cases | G4: =COUNTIF(A:A,"=NEW") -> 0 | O4: CMS-Contempo BM | P4: QA-25 | Q4: CMS Live Test Cases
O5: CMS-Contempo MyEnv | P5: QA-26 | Q5: CMS Sanity Test Cases
A6: Key | B6: Summary | C6: Priority | D6: Component | E6: Epic Link | F6: Test Case Assignee | G6: Estimate | H6: Schedule ? | I6: Execution Priority | J6: Execution By | K6: Test Result Ticket | L6: Comments | M6: Original Estimates | N6: Remaining Estimates | O6: CMS-Deepcreek BM | P6: QA-54 | Q6: Newyse Live Test Cases
A7: QA-3465 | B7: RT_Owner Manager Owner | C7: P3 | D7: OwnerMngr_Owner | E7: QA-1795 | F7: Ritesh Kumar | G7: 4h | H7: Y | I7: P3 | J7: Ritesh Kumar | K7: =HYPERLINK("https://maxxton.atlassian.net/browse/QA-28973","QA-28973") -> QA-28973 | L7: Created on 2026-03-23 for release 2026_Week_13 | M7: 4h | N7: 1h | O7: CMS-Deepcreek MyEnv | P7: QA-55 | Q7: Newyse Sanity Test Cases
A8: QA-3466 | B8: RT_Owner Manager PreSettlement | C8: P3 | D8: OwnerMngr_PreSettlement | E8: QA-1795 | F8: Ritesh Kumar | G8: 4h | H8: Y | I8: P3 | J8: Ritesh Kumar | K8: =HYPERLINK("https://maxxton.atlassian.net/browse/QA-28974","QA-28974") -> QA-28974 | L8: Created on 2026-03-23 for release 2026_Week_13 | M8: 4h | N8: 2h 30m | O8: CMS-Hogenboom BM | P8: QA-71 | Q8: MXTS Sanity Test Cases
A9: QA-3467 | B9: RT_Owner Manager Settlement | C9: P3 | D9: OwnerMngr_Settlement | E9: QA-1795 | F9: Ritesh Kumar | G9: 4h 30m | H9: Y | I9: P3 | J9: Ritesh Kumar | K9: =HYPERLINK("https://maxxton.atlassian.net/browse/QA-28975","QA-28975") -> QA-28975 | L9: Created on 2026-03-23 for release 2026_Week_13 | M9: 4h 30m | N9: 4h 30m | O9: CMS-Hogenboom MyEnv | P9: QA-72 | Q9: MXTS Regression Test Cases
A10: QA-3468 | B10: RT_Owner Manager PostSettlement | C10: P3 | D10: OwnerMngr_PostSettlement | E10: QA-1795 | F10: Ritesh Kumar | G10: 2h | H10: Y | I10: P3 | J10: Ritesh Kumar | K10: =HYPERLINK("https://maxxton.atlassian.net/browse/QA-28976","QA-28976") -> QA-28976 | L10: Created on 2026-03-23 for release 2026_Week_13 | M10: 2h | N10: 2h | O10: CMS-Krim BM
A11: QA-4208 | B11: RT_FnMngr_FM_Configuration | C11: P3 | D11: FnMngr_Ledgers | E11: QA-4207 | F11: Ashwini Kedare | G11: 4h | H11: Y | I11: P3 | J11: Nikhil Gurav | K11: =HYPERLINK("https://maxxton.atlassian.net/browse/QA-28977","QA-28977") -> QA-28977 | L11: Created on 2026-03-23 for release 2026_Week_13 | M11: 4h | N11: 1h 30m | O11: CMS-Krim MyEnv
A12: QA-4209 | B12: RT_FnMngr_Payments_Statements/ Unassigned_Payments | C12: P3 | D12: FnMngr_Revenue_Distri_Rules | E12: QA-4207 | F12: Ashwini Kedare | G12: 4h | H12: Y | I12: P3 | J12: Nikhil Gurav | K12: =HYPERLINK("https://maxxton.atlassian.net/browse/QA-28978","QA-28978") -> QA-28978 | L12: Created on 2026-03-23 for release 2026_Week_13 | M12: 4h | N12: 2h | O12: CMS-PerfectExp BM
A13: QA-4210 | B13: RT_FnMngr_Revenue_Distribution_Process RD/ RD Scheduler/ RD Rules | C13: P3 | D13: FnMngr_Revenue_Distri_Processing | E13: QA-4207 | F13: Nikhil Gurav | G13: 4h | H13: Y | I13: P3 | J13: Nikhil Gurav | K13: =HYPERLINK("https://maxxton.atlassian.net/browse/QA-28979","QA-28979") -> QA-28979 | L13: Created on 2026-03-23 for release 2026_Week_13 | M13: 4h | N13: 2h | O13: CMS-PerfectExp MyEnv
A14: QA-4211 | B14: RT_FnMngr_Financial_Reports_JR/FTR & Financial_Archive | C14: P3 | D14: FnMngr_Trans_Archiver | E14: QA-4207 | F14: Nikhil Gurav | G14: 4h | H14: Y | I14: P3 | J14: Nikhil Gurav | K14: =HYPERLINK("https://maxxton.atlassian.net/browse/QA-28980","QA-28980") -> QA-28980 | L14: Created on 2026-03-23 for release 2026_Week_13 | M14: 4h | N14: 4h | O14: CMS-Roompot BM
A15: QA-23620 | B15: RT_FnMngr_Agent_Settlement | C15: P3 | D15: FnMngr_Trans_Archiver | E15: QA-4207 | F15: Ashwini Kedare | G15: 2h | H15: Y | I15: P3 | J15: Nikhil Gurav | K15: =HYPERLINK("https://maxxton.atlassian.net/browse/QA-28981","QA-28981") -> QA-28981 | L15: Created on 2026-03-23 for release 2026_Week_13 | M15: 2h | N15: 0h | O15: CMS-Roompot MyEnv
A16: =HYPERLINK("https://maxxton.atlassian.net/browse/QA-23955","QA-23955") -> QA-23955 | B16: RT_NF525_Sii Invoices | C16: P3 | D16: FnMngr_Trans_Archiver | E16: QA-4207 | F16: Ritesh Kumar | G16: 4h | H16: Y | I16: P3 | J16: Ritesh Kumar | K16: =HYPERLINK("https://maxxton.atlassian.net/browse/QA-28982","QA-28982") -> QA-28982 | L16: Created on 2026-03-23 for release 2026_Week_13 | M16: 4h | N16: 4h | O16: CMS-Siblu BM
A17: =HYPERLINK("https://maxxton.atlassian.net/browse/QA-23956","QA-23956") -> QA-23956 | B17: RT_NF525_Sii_Jeng | C17: P3 | D17: FnMngr_Trans_Archiver | E17: QA-4207 | F17: Nikhil Gurav | G17: 4h | H17: Y | I17: P3 | J17: Nikhil Gurav | K17: =HYPERLINK("https://maxxton.atlassian.net/browse/QA-28983","QA-28983") -> QA-28983 | L17: Created on 2026-03-23 for release 2026_Week_13 | M17: 4h | N17: 4h | O17: CMS-Siblu MyEnv
O18: MXTS-BackOffice Manager
O19: MXTS-Content Manager
O20: MXTS-Implementation Manager
O21: MXTS-Owner Manager
O22: MXTS-Rate Manager
O23: MXTS-Reservation Manager
O24: MXTS-PaymentService
O25: CMS-RCN MyEnv
O26: CMS-EuroparcsNL MyEnv

Sheet Operations
P1: Components | Q1: Epic
F2: Total Test Cases | G2: =countifs(A:A,"<>NEW",A:A,"<>")-1 -> 27 | P2: CMS-Castle BM | Q2: QA-1 | R2: Newyse Regression Test Cases
F3: Schedule? Y | G3: =countif(H:H,"=Y") -> 17 | P3: CMS-Castle MyEnv | Q3: QA-24 | R3: CMS Regression Test Cases
F4: New Test Cases | G4: =COUNTIF(A:A,"=NEW") -> 0 | P4: CMS-Contempo BM | Q4: QA-25 | R4: CMS Live Test Cases
P5: CMS-Contempo MyEnv | Q5: QA-26 | R5: CMS Sanity Test Cases
A6: Key | B6: Summary | C6: Priority | D6: Component | E6: Epic Link | F6: Test Case Assignee | G6: Estimate | H6: Schedule ? | I6: Execution Priority | J6: Execution By | K6: Test Result Ticket | L6: Comments | M6: Remark | N6: Original Estimates | O6: Remaining Estimates | P6: CMS-Deepcreek BM | Q6: QA-54 | R6: Newyse Live Test Cases
A7: QA-3939 | B7: RT_Planning Creation | C7: P3 | D7: OpnMngr_HK_Dashboard | E7: QA-3936 | F7: Narendra Deshmane | G7: 120m | H7: Y | I7: P3 | J7: Narendra Deshmane | K7: =HYPERLINK("https://maxxton.atlassian.net/browse/QA-29094","QA-29094") -> QA-29094 | L7: Created on 2026-04-03 for release 2026_Week_15 | N7: 120m | O7: 40m | P7: CMS-Deepcreek MyEnv | Q7: QA-55 | R7: Newyse Sanity Test Cases
A8: QA-3940 | B8: RT_HK Dashboard Summary page | C8: P3 | D8: OpnMngr_HK_Dashboard | E8: QA-3936 | F8: Narendra Deshmane | G8: 60m | H8: Y | I8: P3 | J8: Narendra Deshmane | K8: =HYPERLINK("https://maxxton.atlassian.net/browse/QA-29095","QA-29095") -> QA-29095 | L8: Created on 2026-04-03 for release 2026_Week_15 | N8: 60m | O8: 10m | P8: CMS-Hogenboom BM | Q8: QA-71 | R8: MXTS Sanity Test Cases
A9: QA-3941 | B9: RT_Employee Detail Page | C9: P3 | D9: OpnMngr_HK_Dashboard | E9: QA-3936 | F9: Narendra Deshmane | G9: 60m | H9: Y | I9: P3 | J9: Narendra Deshmane | K9: =HYPERLINK("https://maxxton.atlassian.net/browse/QA-29096","QA-29096") -> QA-29096 | L9: Created on 2026-04-03 for release 2026_Week_15 | N9: 60m | O9: 20m | P9: CMS-Hogenboom MyEnv | Q9: QA-72 | R9: MXTS Regression Test Cases
A10: QA-3942 | B10: RT_Planning Dashboard Page | C10: P3 | D10: OpnMngr_HK_PlanningDashboard | E10: QA-3936 | F10: Narendra Deshmane | G10: 60m | H10: Y | I10: P3 | J10: Narendra Deshmane | K10: =HYPERLINK("https://maxxton.atlassian.net/browse/QA-29097","QA-29097") -> QA-29097 | L10: Created on 2026-04-03 for release 2026_Week_15 | N10: 60m | O10: 20m | P10: CMS-Krim BM
A11: QA-3943 | B11: RT_Assign Employee Page | C11: P3 | D11: OpnMngr_HK_PlanningDashboard | E11: QA-3936 | F11: Narendra Deshmane | G11: 60m | H11: Y | I11: P3 | J11: Narendra Deshmane | K11: =HYPERLINK("https://maxxton.atlassian.net/browse/QA-29098","QA-29098") -> QA-29098 | L11: Created on 2026-04-03 for release 2026_Week_15 | N11: 60m | O11: 10m | P11: CMS-Krim MyEnv
A12: QA-3944 | B12: RT_Task Configuation | C12: P3 | D12: OpnMngr_HK_Config | E12: QA-3936 | F12: Narendra Deshmane | G12: 60m | H12: Y | I12: P3 | J12: Narendra Deshmane | K12: =HYPERLINK("https://maxxton.atlassian.net/browse/QA-29099","QA-29099") -> QA-29099 | L12: Created on 2026-04-03 for release 2026_Week_15 | N12: 60m | O12: 15m | P12: CMS-PerfectExp BM
A13: QA-3945 | B13: RT_Sector Configuration | C13: P3 | D13: OpnMngr_HK_Config | E13: QA-3936 | F13: Narendra Deshmane | G13: 60m | H13: N | I13: P3 | J13: Narendra Deshmane | K13: =HYPERLINK("https://maxxton.atlassian.net/browse/QA-22621","QA-22621") -> QA-22621 | L13: Created on 2025-02-20 for release 2025_Week_09 | M13: Merged in QA-3944 | N13: 60m | O13: 10m | P13: CMS-PerfectExp MyEnv
A14: QA-3946 | B14: RT_Maint Dashboard Summary Page | C14: P3 | D14: OpnMngr_Maint_Dashboard | E14: QA-3937 | F14: Narendra Deshmane | G14: 60m | H14: N | I14: P3 | J14: Narendra Deshmane | K14: =HYPERLINK("https://maxxton.atlassian.net/browse/QA-22622","QA-22622") -> QA-22622 | L14: Created on 2025-02-20 for release 2025_Week_09 | M14: Merged in QA-3947 | N14: 60m | O14: 10m | P14: CMS-Roompot BM
A15: QA-3947 | B15: RT_Work Order Daily Operation | C15: P3 | D15: OpnMngr_Maint_Dashboard | E15: QA-3937 | F15: Narendra Deshmane | G15: 90m | H15: Y | I15: P3 | J15: Narendra Deshmane | K15: =HYPERLINK("https://maxxton.atlassian.net/browse/QA-29100","QA-29100") -> QA-29100 | L15: Created on 2026-04-03 for release 2026_Week_15 | N15: 60m | O15: 10m | P15: CMS-Roompot MyEnv
A16: QA-3948 | B16: RT_Work Order Creat/edit | C16: P3 | D16: OpnMngr_Maint_WorkOrderList | E16: QA-3937 | F16: Narendra Deshmane | G16: 60m | H16: Y | I16: P3 | J16: Narendra Deshmane | K16: =HYPERLINK("https://maxxton.atlassian.net/browse/QA-29101","QA-29101") -> QA-29101 | L16: Created on 2026-04-03 for release 2026_Week_15 | N16: 60m | O16: 10m | P16: CMS-Siblu BM
A17: QA-3949 | B17: RT_Work Order Invoicing | C17: P3 | D17: OpnMngr_Maint_WorkOrderList | E17: QA-3937 | F17: Narendra Deshmane | G17: 60m | H17: N | I17: P3 | J17: Narendra Deshmane | K17: =HYPERLINK("https://maxxton.atlassian.net/browse/QA-22625","QA-22625") -> QA-22625 | L17: Created on 2025-02-20 for release 2025_Week_09 | M17: Merged in QA-3948 | N17: 60m | O17: 20m | P17: CMS-Siblu MyEnv
A18: QA-3950 | B18: RT_WO Categories Configuration | C18: P3 | D18: OpnMngr_Maint_Config | E18: QA-3937 | F18: Narendra Deshmane | G18: 60m | H18: Y | I18: P3 | J18: Narendra Deshmane | K18: =HYPERLINK("https://maxxton.atlassian.net/browse/QA-29102","QA-29102") -> QA-29102 | L18: Created on 2026-04-03 for release 2026_Week_15 | N18: 60m | O18: 5m | P18: MXTS-BackOffice Manager
A19: QA-3951 | B19: RT_App HK Dashboard | C19: P3 | D19: OpnMngr_App_HK | E19: QA-3938 | F19: Narendra Deshmane | G19: 60m | H19: N | I19: P3 | J19: Narendra Deshmane | K19: =HYPERLINK("https://maxxton.atlassian.net/browse/QA-22627","QA-22627") -> QA-22627 | L19: Created on 2025-02-20 for release 2025_Week_09 | M19: Merged in QA-3952 | N19: 60m | O19: 60m | P19: MXTS-Content Manager
A20: QA-3952 | B20: RT_App Task Detail Screen | C20: P3 | D20: OpnMngr_App_HK | E20: QA-3938 | F20: Narendra Deshmane | G20: 60m | H20: Y | I20: P3 | J20: Narendra Deshmane | K20: =HYPERLINK("https://maxxton.atlassian.net/browse/QA-29103","QA-29103") -> QA-29103 | L20: Created on 2026-04-03 for release 2026_Week_15 | N20: 60m | O20: 60m | P20: MXTS-Implementation Manager
A21: QA-3953 | B21: RT_App Maint Dashboard | C21: P3 | D21: OpnMngr_App_Maint | E21: QA-3938 | F21: Narendra Deshmane | G21: 60m | H21: N | I21: P3 | J21: Narendra Deshmane | K21: =HYPERLINK("https://maxxton.atlassian.net/browse/QA-22629","QA-22629") -> QA-22629 | L21: Created on 2025-02-20 for release 2025_Week_09 | M21: Merged in QA-3954 | N21: 60m | O21: 60m | P21: MXTS-Owner Manager
A22: QA-3954 | B22: RT_App Work Order Detail Screen | C22: P3 | D22: OpnMngr_App_Maint | E22: QA-3938 | F22: Narendra Deshmane | G22: 60m | H22: Y | I22: P3 | J22: Narendra Deshmane | K22: =HYPERLINK("https://maxxton.atlassian.net/browse/QA-29104","QA-29104") -> QA-29104 | L22: Created on 2026-04-03 for release 2026_Week_15 | N22: 60m | O22: 60m | P22: MXTS-Rate Manager
A23: QA-7395 | B23: RT_Periodical Tasks | C23: P3 | D23: OpnMngr_Perio_task | E23: QA-3937 | F23: Narendra Deshmane | G23: 60m | H23: Y | I23: P3 | J23: Narendra Deshmane | K23: =HYPERLINK("https://maxxton.atlassian.net/browse/QA-29105","QA-29105") -> QA-29105 | L23: Created on 2026-04-03 for release 2026_Week_15 | N23: 60m | O23: 20m | P23: MXTS-Reservation Manager
A24: QA-7615 | B24: RT_Inspection | C24: P3 | D24: OpnMngr_Maint_Inspection | E24: QA-3937 | F24: Narendra Deshmane | G24: 90m | H24: Y | I24: P3 | J24: Narendra Deshmane | K24: =HYPERLINK("https://maxxton.atlassian.net/browse/QA-29106","QA-29106") -> QA-29106 | L24: Created on 2026-04-03 for release 2026_Week_15 | N24: 90m | O24: 20m | P24: MXTS-PaymentService
A25: QA-10282 | B25: RT_WO Item Configuration | C25: P3 | D25: OpnMngr_Maint_Config | E25: QA-3937 | F25: Narendra Deshmane | G25: 60m | H25: N | I25: P3 | J25: Narendra Deshmane | K25: =HYPERLINK("https://maxxton.atlassian.net/browse/QA-22633","QA-22633") -> QA-22633 | L25: Created on 2025-02-20 for release 2025_Week_09 | M25: Merged in QA-3950 | N25: 60m | O25: 5m | P25: CMS-RCN MyEnv
A26: QA-10283 | B26: RT_WO Area Configuration | C26: P3 | D26: OpnMngr_Maint_Config | E26: QA-3937 | F26: Narendra Deshmane | G26: 60m | H26: N | I26: P3 | J26: Narendra Deshmane | K26: =HYPERLINK("https://maxxton.atlassian.net/browse/QA-22634","QA-22634") -> QA-22634 | L26: Created on 2025-02-20 for release 2025_Week_09 | M26: Merged in QA-3950 | N26: 60m | O26: 5m | P26: CMS-EuroparcsNL MyEnv
A27: QA-10284 | B27: RT_WO Materials Configuration | C27: P3 | D27: OpnMngr_Maint_Config | E27: QA-3937 | F27: Narendra Deshmane | G27: 60m | H27: Y | I27: P3 | J27: Narendra Deshmane | K27: =HYPERLINK("https://maxxton.atlassian.net/browse/QA-29107","QA-29107") -> QA-29107 | L27: Created on 2026-04-03 for release 2026_Week_15 | N27: 60m | O27: 5m
A28: QA-10285 | B28: RT_Periodical Task Configuration | C28: P3 | D28: OpnMngr_Maint_Config | E28: QA-3937 | F28: Narendra Deshmane | G28: 60m | H28: Y | I28: P3 | J28: Narendra Deshmane | K28: =HYPERLINK("https://maxxton.atlassian.net/browse/QA-29108","QA-29108") -> QA-29108 | L28: Created on 2026-04-03 for release 2026_Week_15 | N28: 60m | O28: 20m
A29: QA-16460 | B29: RT_App Periodical Task | C29: P3 | D29: OpnMngr_App_Maint | E29: QA-3938 | F29: Narendra Deshmane | G29: 60m | H29: Y | I29: P3 | J29: Narendra Deshmane | K29: =HYPERLINK("https://maxxton.atlassian.net/browse/QA-29109","QA-29109") -> QA-29109 | L29: Created on 2026-04-03 for release 2026_Week_15 | N29: 60m | O29: 60m
A30: QA-16461 | B30: RT_App Meter Reading | C30: P3 | D30: OpnMngr_App_Maint | E30: QA-3938 | F30: Narendra Deshmane | G30: 60m | H30: N | I30: P3 | J30: Narendra Deshmane | K30: =HYPERLINK("https://maxxton.atlassian.net/browse/QA-22638","QA-22638") -> QA-22638 | L30: Created on 2025-02-20 for release 2025_Week_09 | M30: Merged in QA-16460 | N30: 60m | O30: 60m
A31: QA-16462 | B31: RT_App Barrier Control and Inspection | C31: P3 | D31: OpnMngr_App_Maint | E31: QA-3938 | F31: Narendra Deshmane | G31: 60m | H31: N | I31: P3 | J31: Narendra Deshmane | K31: =HYPERLINK("https://maxxton.atlassian.net/browse/QA-27233","QA-27233") -> QA-27233 | L31: Created on 2025-11-27 for release 2025_Week_49 | N31: 60m | O31: 60m
A32: QA-19284 | B32: RT_WO Material Supplier Configuration | C32: P3 | D32: OpnMngr_Maint_Config | E32: QA-3937 | F32: Narendra Deshmane | G32: 60m | H32: N | I32: P3 | J32: Narendra Deshmane | K32: =HYPERLINK("https://maxxton.atlassian.net/browse/QA-22639","QA-22639") -> QA-22639 | L32: Created on 2025-02-20 for release 2025_Week_09 | M32: Merged in QA-10284 | N32: 60m | O32: 5m
A33: =HYPERLINK("https://maxxton.atlassian.net/browse/QA-22962","QA-22962") -> QA-22962 | B33: RT_Work schedule module | C33: P3 | D33: OpnMngr_Maint_Config | E33: QA-3937 | F33: Narendra Deshmane | G33: 60m | H33: Y | I33: P3 | J33: Narendra Deshmane | K33: =HYPERLINK("https://maxxton.atlassian.net/browse/QA-29110","QA-29110") -> QA-29110 | L33: Created on 2026-04-03 for release 2026_Week_15 | N33: 90m | O33: 20m

Sheet Rates
O1: Components | P1: Epic
F2: Total Test Cases | G2: =countifs(A:A,"<>NEW",A:A,"<>")-1 -> 10 | O2: CMS-Castle BM | P2: QA-1 | Q2: Newyse Regression Test Cases
F3: Schedule? Y | G3: =countif(H:H,"=Y") -> 6 | O3: CMS-Castle MyEnv | P3: QA-24 | Q3: CMS Regression Test Cases
F4: New Test Cases | G4: =COUNTIF(A:A,"=NEW") -> 0 | O4: CMS-Contempo BM | P4: QA-25 | Q4: CMS Live Test Cases
E5: API token | F5: ciTSS7f3VPYW8Af3i2ZO923A | H5: 2025_Week_17 | O5: CMS-Contempo MyEnv | P5: QA-26 | Q5: CMS Sanity Test Cases
A6: Key | B6: Summary | C6: Priority | D6: Component | E6: Epic Link | F6: Test Case Assignee | G6: Estimate | H6: Schedule ? | I6: Execution Priority | J6: Execution By | K6: Test Result Ticket | L6: Comments | M6: Original Estimates | N6: Remaining Estimates | O6: CMS-Deepcreek BM | P6: QA-54 | Q6: Newyse Live Test Cases
A7: QA-3046 | B7: RT_Rate Screen | C7: P3 | D7: RtMngr_Rates | E7: QA-1782 | F7: Mahesh Pawar | G7: 2h | H7: N | I7: P3 | J7: Mahesh Pawar | K7: =HYPERLINK("https://maxxton.atlassian.net/browse/QA-24171","QA-24171") -> QA-24171 | L7: Created on 2025-05-16 for release 2025_Week_21 | M7: 1h | N7: 30m | O7: CMS-Deepcreek MyEnv | P7: QA-55 | Q7: Newyse Sanity Test Cases
A8: QA-3056 | B8: RT_Accomodation Type | C8: P3 | D8: RtMngr_AccomodationType | E8: QA-1782 | F8: Mahesh Pawar | G8: 2h | H8: Y | I8: P3 | J8: Mahesh Pawar | K8: =HYPERLINK("https://maxxton.atlassian.net/browse/QA-28953","QA-28953") -> QA-28953 | L8: Created on 2026-03-22 for release 2026_Week_13 | M8: 2h | N8: 20m | O8: CMS-PerfectExp MyEnv
A9: QA-3047 | B9: RT_Rate Types | C9: P3 | D9: RtMngr_RateTypes | E9: QA-1782 | F9: Mahesh Pawar | G9: 2h | H9: Y | I9: P3 | J9: Mahesh Pawar | K9: =HYPERLINK("https://maxxton.atlassian.net/browse/QA-28954","QA-28954") -> QA-28954 | L9: Created on 2026-03-22 for release 2026_Week_13 | M9: 2h | N9: 30m | O9: CMS-Krim BM
A10: =HYPERLINK("https://maxxton.atlassian.net/browse/QA-9473","QA-9473") -> QA-9473 | B10: RT_Package | C10: P3 | D10: RtMngr_Offer | E10: QA-1782 | F10: Mahesh Pawar | G10: 2h | H10: N | I10: P3 | J10: Mahesh Pawar | K10: =HYPERLINK("https://maxxton.atlassian.net/browse/QA-27792","QA-27792") -> QA-27792 | L10: Created on 2026-01-12 for release 2026_Week_03 | M10: 3h | N10: 60m | O10: MXTS-BackOffice Manager
A11: =HYPERLINK("https://maxxton.atlassian.net/browse/QA-9476","QA-9476") -> QA-9476 | B11: RT_Offer/Package Import | C11: P3 | D11: RtMngr_Offer | E11: QA-1782 | F11: Mahesh Pawar | G11: 2h | H11: Y | I11: P3 | J11: Mahesh Pawar | K11: =HYPERLINK("https://maxxton.atlassian.net/browse/QA-28955","QA-28955") -> QA-28955 | L11: Created on 2026-03-22 for release 2026_Week_13 | M11: 1h | N11: 60m | O11: MXTS-Content Manager
A12: QA-17104 | B12: RT_Offer | C12: P3 | D12: RtMngr_Offer | E12: QA-1782 | F12: Mahesh Pawar | G12: 2h | H12: Y | I12: P3 | J12: Mahesh Pawar | K12: =HYPERLINK("https://maxxton.atlassian.net/browse/QA-28956","QA-28956") -> QA-28956 | L12: Created on 2026-03-22 for release 2026_Week_13 | M12: 3h | N12: 60m | O12: MXTS-Implementation Manager
A13: QA-3058 | B13: RT_Rentability Set | C13: P3 | D13: RtMngr_RentabilitySet | E13: QA-1782 | F13: Mahesh Pawar | G13: 2h | H13: Y | I13: P3 | J13: Mahesh Pawar | K13: =HYPERLINK("https://maxxton.atlassian.net/browse/QA-28957","QA-28957") -> QA-28957 | L13: Created on 2026-03-22 for release 2026_Week_13 | M13: 2h | N13: 30m | O13: CMS-Roompot MyEnv
A14: QA-3060 | B14: RT_Batch Updates | C14: P3 | D14: RtMngr_Import&BatchUpdates | E14: QA-1782 | F14: Mahesh Pawar | G14: 2h | H14: N | I14: P3 | J14: Mahesh Pawar | K14: =HYPERLINK("https://maxxton.atlassian.net/browse/QA-27795","QA-27795") -> QA-27795 | L14: Created on 2026-01-12 for release 2026_Week_03 | M14: 2h | N14: 30m | O14: CMS-Siblu MyEnv
A15: QA-3059 | B15: RT_Rates Imports | C15: P3 | D15: RtMngr_Import&BatchUpdates | E15: QA-1782 | F15: Mahesh Pawar | G15: 2h | H15: N | I15: P3 | J15: Mahesh Pawar | K15: =HYPERLINK("https://maxxton.atlassian.net/browse/QA-24759","QA-24759") -> QA-24759 | L15: Created on 2025-06-27 for release 2025_Week_27 | M15: 1h | N15: 60m | O15: CMS-Siblu BM
A16: QA-19070 | B16: RT_Vouchers | C16: P3 | D16: RtMngr_Voucher | E16: QA-1782 | F16: Mahesh Pawar | G16: 2h | H16: Y | I16: P3 | J16: Mahesh Pawar | K16: =HYPERLINK("https://maxxton.atlassian.net/browse/QA-28958","QA-28958") -> QA-28958 | L16: Created on 2026-03-22 for release 2026_Week_13 | M16: 1h | N16: 30m | O16: CMS-Siblu BM
L17: Total Hrs | M17: 18h | N17: 7h

Sheet ThirdPartyAPI(New)
F2: Total Test Cases | G2: =countifs(A:A,"<>NEW",A:A,"<>")-1 -> 42 | O2: Components | P2: Epic
F3: Schedule? Y | G3: =countif(H:H,"=Y") -> 14
F4: New Test Cases | G4: =COUNTIF(A:A,"=NEW") -> 0
O5: API_BatchEventDelta | P5: QA-26 | Q5: CMS Sanity Test Cases
A6: Key | B6: Summary | C6: Priority | D6: Component | E6: Epic Link | F6: Test Case Assignee | G6: Estimate | H6: Schedule ? | I6: Execution Priority | J6: Execution By | K6: Test Result Ticket | L6: Comments | M6: Original Estimates | N6: Remaining Estimates | O6: API_Owner Related | P6: QA-54 | Q6: Newyse Live Test Cases
A7: QA-1432 | B7: RT_API_Property_Details_Accommodationtypes_P1 | C7: P1 | D7: TPI_AccommodationTpes | E7: QA-1223 | F7: Anup Sinha | G7: 2h | H7: Y | I7: P1 | J7: Anup Sinha | K7: =HYPERLINK("https://maxxton.atlassian.net/browse/QA-28959","QA-28959") -> QA-28959 | L7: Created on 2026-03-23 for release 2026_Week_13 | M7: 2 | P7: QA-72 | Q7: MXTS Regression Test Cases
A8: QA-1501 | B8: RT_API_Property_Details_Amenity_P1 | C8: P1 | D8: TPI_Amenity | E8: QA-1223 | F8: Aparna Shinde | G8: 1h | H8: Y | I8: P1 | J8: Aparna Shinde | K8: =HYPERLINK("https://maxxton.atlassian.net/browse/QA-28960","QA-28960") -> QA-28960 | L8: Created on 2026-03-23 for release 2026_Week_13 | M8: 30m
A9: QA-1475 | B9: RT_API_Property_Details_AddOn_P1 | C9: P1 | D9: TPI_AddOn | E9: QA-1223 | F9: Anup Sinha | G9: 1h | H9: Y | I9: P1 | J9: Aparna Shinde | K9: =HYPERLINK("https://maxxton.atlassian.net/browse/QA-28961","QA-28961") -> QA-28961 | L9: Created on 2026-03-23 for release 2026_Week_13 | M9: 1
A10: QA-1506 | B10: API_Master Data_P1 | C10: P1 | D10: TPI_MasterData | E10: QA-1223 | F10: Aparna Shinde | G10: 2h | H10: Y | I10: P1 | J10: Aparna Shinde | K10: =HYPERLINK("https://maxxton.atlassian.net/browse/QA-28962","QA-28962") -> QA-28962 | L10: Created on 2026-03-23 for release 2026_Week_13 | M10: 45m
A11: QA-1534 | B11: API_Customer_P1 | C11: P1 | D11: TPI_Customer | E11: QA-1223 | F11: Aparna Shinde | G11: 4h | H11: Y | I11: P1 | J11: Anup Sinha | K11: =HYPERLINK("https://maxxton.atlassian.net/browse/QA-28963","QA-28963") -> QA-28963 | L11: Created on 2026-03-23 for release 2026_Week_13 | M11: 1
